<?xml version="1.0"?>
<robot xmlns:xacro="http://www.ros.org/wiki/xacro" name="igvc">

  <!-- Serial port (overridable via xacro arg) -->
  <xacro:arg name="serial_port" default="/dev/ttyACM0" />

  <!-- Drivetrain parameters -->
  <xacro:property name="wheel_separation" value="0.508" />
  <xacro:property name="wheel_radius"     value="0.0345" />

  <!-- Base link -->
  <link name="base_link">
    <visual>
      <geometry><box size="0.6 0.5 0.2" /></geometry>
    </visual>
  </link>

  <link name="base_footprint" />
  <joint name="base_joint" type="fixed">
    <parent link="base_footprint" />
    <child  link="base_link" />
    <origin xyz="0 0 ${wheel_radius}" rpy="0 0 0" />
  </joint>

  <!-- Left wheel -->
  <link name="left_wheel">
    <visual>
      <geometry><cylinder radius="${wheel_radius}" length="0.05" /></geometry>
      <material name="black"><color rgba="0.1 0.1 0.1 1" /></material>
    </visual>
  </link>
  <joint name="left_wheel_joint" type="continuous">
    <parent link="base_link" />
    <child  link="left_wheel" />
    <origin xyz="0 ${wheel_separation/2} 0" rpy="${-pi/2} 0 0" />
    <axis xyz="0 0 1" />
  </joint>

  <!-- Right wheel -->
  <link name="right_wheel">
    <visual>
      <geometry><cylinder radius="${wheel_radius}" length="0.05" /></geometry>
      <material name="black"><color rgba="0.1 0.1 0.1 1" /></material>
    </visual>
  </link>
  <joint name="right_wheel_joint" type="continuous">
    <parent link="base_link" />
    <child  link="right_wheel" />
    <origin xyz="0 ${-wheel_separation/2} 0" rpy="${-pi/2} 0 0" />
    <axis xyz="0 0 1" />
  </joint>

  <!-- ros2_control hardware interface -->
  <ros2_control name="igvc_hardware" type="system">
    <hardware>
      <plugin>igvc_control/IgvcHardware</plugin>
      <param name="serial_port">$(arg serial_port)</param>
      <param name="gear_ratio">12.75</param>
      <param name="max_motor_rpm">5700</param>
      <param name="left_motor_inverted">false</param>
      <param name="right_motor_inverted">true</param>
    </hardware>

    <joint name="left_wheel_joint">
      <command_interface name="velocity" />
      <state_interface name="position" />
      <state_interface name="velocity" />
    </joint>

    <joint name="right_wheel_joint">
      <command_interface name="velocity" />
      <state_interface name="position" />
      <state_interface name="velocity" />
    </joint>
  </ros2_control>

</robot>
